[2022-11-13T06:36:50.051+0000] {taskinstance.py:1165} INFO - Dependencies all met for <TaskInstance: Assignment-7.copy_views manual__2022-11-13T06:36:48.864713+00:00 [queued]>
[2022-11-13T06:36:50.070+0000] {taskinstance.py:1165} INFO - Dependencies all met for <TaskInstance: Assignment-7.copy_views manual__2022-11-13T06:36:48.864713+00:00 [queued]>
[2022-11-13T06:36:50.071+0000] {taskinstance.py:1362} INFO - 
--------------------------------------------------------------------------------
[2022-11-13T06:36:50.071+0000] {taskinstance.py:1363} INFO - Starting attempt 1 of 1
[2022-11-13T06:36:50.071+0000] {taskinstance.py:1364} INFO - 
--------------------------------------------------------------------------------
[2022-11-13T06:36:50.107+0000] {taskinstance.py:1383} INFO - Executing <Task(PythonOperator): copy_views> on 2022-11-13 06:36:48.864713+00:00
[2022-11-13T06:36:50.117+0000] {standard_task_runner.py:54} INFO - Started process 897 to run task
[2022-11-13T06:36:50.125+0000] {standard_task_runner.py:82} INFO - Running: ['***', 'tasks', 'run', 'Assignment-7', 'copy_views', 'manual__2022-11-13T06:36:48.864713+00:00', '--job-id', '8', '--raw', '--subdir', 'DAGS_FOLDER/videos_dag.py', '--cfg-path', '/tmp/tmpcubmokyg']
[2022-11-13T06:36:50.125+0000] {standard_task_runner.py:83} INFO - Job 8: Subtask copy_views
[2022-11-13T06:36:50.127+0000] {dagbag.py:525} INFO - Filling up the DagBag from /opt/***/dags/videos_dag.py
[2022-11-13T06:36:50.313+0000] {task_command.py:384} INFO - Running <TaskInstance: Assignment-7.copy_views manual__2022-11-13T06:36:48.864713+00:00 [running]> on host b5152e7b72a3
[2022-11-13T06:36:50.445+0000] {taskinstance.py:1592} INFO - Exporting the following env vars:
AIRFLOW_CTX_DAG_OWNER=***
AIRFLOW_CTX_DAG_ID=Assignment-7
AIRFLOW_CTX_TASK_ID=copy_views
AIRFLOW_CTX_EXECUTION_DATE=2022-11-13T06:36:48.864713+00:00
AIRFLOW_CTX_TRY_NUMBER=1
AIRFLOW_CTX_DAG_RUN_ID=manual__2022-11-13T06:36:48.864713+00:00
[2022-11-13T06:36:51.109+0000] {taskinstance.py:1851} ERROR - Task failed with exception
Traceback (most recent call last):
  File "/home/airflow/.local/lib/python3.7/site-packages/sqlalchemy/engine/base.py", line 1901, in _execute_context
    cursor, statement, parameters, context
  File "/home/airflow/.local/lib/python3.7/site-packages/sqlalchemy/engine/default.py", line 736, in do_execute
    cursor.execute(statement, parameters)
psycopg2.errors.ForeignKeyViolation: insert or update on table "views" violates foreign key constraint "views_video_id_fkey"
DETAIL:  Key (video_id)=(38042797-7000-407e-8fe1-e4a114b8d48c) is not present in table "videos".


The above exception was the direct cause of the following exception:

Traceback (most recent call last):
  File "/home/airflow/.local/lib/python3.7/site-packages/airflow/operators/python.py", line 175, in execute
    return_value = self.execute_callable()
  File "/home/airflow/.local/lib/python3.7/site-packages/airflow/operators/python.py", line 193, in execute_callable
    return self.python_callable(*self.op_args, **self.op_kwargs)
  File "/opt/airflow/dags/importing_data/views.py", line 64, in copy_views
    run_query_destination(query, commit=True)
  File "/opt/airflow/dags/utils.py", line 48, in run_query_destination
    return get_query(get_engine_destination(), query, commit)
  File "/opt/airflow/dags/utils.py", line 39, in get_query
    conn.execute(query)
  File "/home/airflow/.local/lib/python3.7/site-packages/sqlalchemy/future/engine.py", line 281, in execute
    statement, parameters, execution_options or NO_OPTIONS
  File "/home/airflow/.local/lib/python3.7/site-packages/sqlalchemy/engine/base.py", line 1705, in _execute_20
    return meth(self, args_10style, kwargs_10style, execution_options)
  File "/home/airflow/.local/lib/python3.7/site-packages/sqlalchemy/sql/elements.py", line 334, in _execute_on_connection
    self, multiparams, params, execution_options
  File "/home/airflow/.local/lib/python3.7/site-packages/sqlalchemy/engine/base.py", line 1582, in _execute_clauseelement
    cache_hit=cache_hit,
  File "/home/airflow/.local/lib/python3.7/site-packages/sqlalchemy/engine/base.py", line 1944, in _execute_context
    e, statement, parameters, cursor, context
  File "/home/airflow/.local/lib/python3.7/site-packages/sqlalchemy/engine/base.py", line 2125, in _handle_dbapi_exception
    sqlalchemy_exception, with_traceback=exc_info[2], from_=e
  File "/home/airflow/.local/lib/python3.7/site-packages/sqlalchemy/util/compat.py", line 208, in raise_
    raise exception
  File "/home/airflow/.local/lib/python3.7/site-packages/sqlalchemy/engine/base.py", line 1901, in _execute_context
    cursor, statement, parameters, context
  File "/home/airflow/.local/lib/python3.7/site-packages/sqlalchemy/engine/default.py", line 736, in do_execute
    cursor.execute(statement, parameters)
sqlalchemy.exc.IntegrityError: (psycopg2.errors.ForeignKeyViolation) insert or update on table "views" violates foreign key constraint "views_video_id_fkey"
DETAIL:  Key (video_id)=(38042797-7000-407e-8fe1-e4a114b8d48c) is not present in table "videos".

[SQL: INSERT INTO views VALUES ('a63380a1-799f-4109-a5f9-0a700bca0dc5', '38ad315a-ff36-4762-9762-64d96acafc24', '38042797-7000-407e-8fe1-e4a114b8d48c', '2003-01-31 12:26:55.370365', '2003-01-31 12:31:18.872284')]
(Background on this error at: https://sqlalche.me/e/14/gkpj)
[2022-11-13T06:36:51.134+0000] {taskinstance.py:1406} INFO - Marking task as FAILED. dag_id=Assignment-7, task_id=copy_views, execution_date=20221113T063648, start_date=20221113T063650, end_date=20221113T063651
[2022-11-13T06:36:51.161+0000] {standard_task_runner.py:107} ERROR - Failed to execute job 8 for task copy_views ((psycopg2.errors.ForeignKeyViolation) insert or update on table "views" violates foreign key constraint "views_video_id_fkey"
DETAIL:  Key (video_id)=(38042797-7000-407e-8fe1-e4a114b8d48c) is not present in table "videos".

[SQL: INSERT INTO views VALUES ('a63380a1-799f-4109-a5f9-0a700bca0dc5', '38ad315a-ff36-4762-9762-64d96acafc24', '38042797-7000-407e-8fe1-e4a114b8d48c', '2003-01-31 12:26:55.370365', '2003-01-31 12:31:18.872284')]
(Background on this error at: https://sqlalche.me/e/14/gkpj); 897)
[2022-11-13T06:36:51.194+0000] {local_task_job.py:164} INFO - Task exited with return code 1
[2022-11-13T06:36:51.273+0000] {local_task_job.py:273} INFO - 0 downstream tasks scheduled from follow-on schedule check
