[2022-11-13T16:39:05.559+0000] {taskinstance.py:1165} INFO - Dependencies all met for <TaskInstance: Assignment-7.copy_views manual__2022-11-13T16:39:04.005022+00:00 [queued]>
[2022-11-13T16:39:05.586+0000] {taskinstance.py:1165} INFO - Dependencies all met for <TaskInstance: Assignment-7.copy_views manual__2022-11-13T16:39:04.005022+00:00 [queued]>
[2022-11-13T16:39:05.587+0000] {taskinstance.py:1362} INFO - 
--------------------------------------------------------------------------------
[2022-11-13T16:39:05.587+0000] {taskinstance.py:1363} INFO - Starting attempt 1 of 1
[2022-11-13T16:39:05.587+0000] {taskinstance.py:1364} INFO - 
--------------------------------------------------------------------------------
[2022-11-13T16:39:05.620+0000] {taskinstance.py:1383} INFO - Executing <Task(PythonOperator): copy_views> on 2022-11-13 16:39:04.005022+00:00
[2022-11-13T16:39:05.630+0000] {standard_task_runner.py:54} INFO - Started process 4476 to run task
[2022-11-13T16:39:05.642+0000] {standard_task_runner.py:82} INFO - Running: ['***', 'tasks', 'run', 'Assignment-7', 'copy_views', 'manual__2022-11-13T16:39:04.005022+00:00', '--job-id', '11', '--raw', '--subdir', 'DAGS_FOLDER/videos_dag.py', '--cfg-path', '/tmp/tmprbqre3_o']
[2022-11-13T16:39:05.643+0000] {standard_task_runner.py:83} INFO - Job 11: Subtask copy_views
[2022-11-13T16:39:05.647+0000] {dagbag.py:525} INFO - Filling up the DagBag from /opt/***/dags/videos_dag.py
[2022-11-13T16:39:27.107+0000] {task_command.py:384} INFO - Running <TaskInstance: Assignment-7.copy_views manual__2022-11-13T16:39:04.005022+00:00 [running]> on host b5152e7b72a3
[2022-11-13T16:39:27.523+0000] {taskinstance.py:1592} INFO - Exporting the following env vars:
AIRFLOW_CTX_DAG_OWNER=***
AIRFLOW_CTX_DAG_ID=Assignment-7
AIRFLOW_CTX_TASK_ID=copy_views
AIRFLOW_CTX_EXECUTION_DATE=2022-11-13T16:39:04.005022+00:00
AIRFLOW_CTX_TRY_NUMBER=1
AIRFLOW_CTX_DAG_RUN_ID=manual__2022-11-13T16:39:04.005022+00:00
[2022-11-13T16:39:28.389+0000] {taskinstance.py:1851} ERROR - Task failed with exception
Traceback (most recent call last):
  File "/home/airflow/.local/lib/python3.7/site-packages/sqlalchemy/engine/base.py", line 1901, in _execute_context
    cursor, statement, parameters, context
  File "/home/airflow/.local/lib/python3.7/site-packages/sqlalchemy/engine/default.py", line 736, in do_execute
    cursor.execute(statement, parameters)
psycopg2.errors.ForeignKeyViolation: insert or update on table "views" violates foreign key constraint "views_video_id_fkey"
DETAIL:  Key (video_id)=(bf3182e2-39d2-4ba6-9bc5-381bd6af5552) is not present in table "videos".


The above exception was the direct cause of the following exception:

Traceback (most recent call last):
  File "/home/airflow/.local/lib/python3.7/site-packages/airflow/operators/python.py", line 175, in execute
    return_value = self.execute_callable()
  File "/home/airflow/.local/lib/python3.7/site-packages/airflow/operators/python.py", line 193, in execute_callable
    return self.python_callable(*self.op_args, **self.op_kwargs)
  File "/opt/airflow/dags/importing_data/views.py", line 74, in copy_views
    run_query_destination(query, commit=True)
  File "/opt/airflow/dags/utils.py", line 48, in run_query_destination
    return get_query(get_engine_destination(), query, commit)
  File "/opt/airflow/dags/utils.py", line 39, in get_query
    conn.execute(query)
  File "/home/airflow/.local/lib/python3.7/site-packages/sqlalchemy/future/engine.py", line 281, in execute
    statement, parameters, execution_options or NO_OPTIONS
  File "/home/airflow/.local/lib/python3.7/site-packages/sqlalchemy/engine/base.py", line 1705, in _execute_20
    return meth(self, args_10style, kwargs_10style, execution_options)
  File "/home/airflow/.local/lib/python3.7/site-packages/sqlalchemy/sql/elements.py", line 334, in _execute_on_connection
    self, multiparams, params, execution_options
  File "/home/airflow/.local/lib/python3.7/site-packages/sqlalchemy/engine/base.py", line 1582, in _execute_clauseelement
    cache_hit=cache_hit,
  File "/home/airflow/.local/lib/python3.7/site-packages/sqlalchemy/engine/base.py", line 1944, in _execute_context
    e, statement, parameters, cursor, context
  File "/home/airflow/.local/lib/python3.7/site-packages/sqlalchemy/engine/base.py", line 2125, in _handle_dbapi_exception
    sqlalchemy_exception, with_traceback=exc_info[2], from_=e
  File "/home/airflow/.local/lib/python3.7/site-packages/sqlalchemy/util/compat.py", line 208, in raise_
    raise exception
  File "/home/airflow/.local/lib/python3.7/site-packages/sqlalchemy/engine/base.py", line 1901, in _execute_context
    cursor, statement, parameters, context
  File "/home/airflow/.local/lib/python3.7/site-packages/sqlalchemy/engine/default.py", line 736, in do_execute
    cursor.execute(statement, parameters)
sqlalchemy.exc.IntegrityError: (psycopg2.errors.ForeignKeyViolation) insert or update on table "views" violates foreign key constraint "views_video_id_fkey"
DETAIL:  Key (video_id)=(bf3182e2-39d2-4ba6-9bc5-381bd6af5552) is not present in table "videos".

[SQL: INSERT INTO views VALUES ('d7433450-dd20-4162-97ec-810ae8bc45af', 'b4c28b89-6d8d-4b47-9d71-160643e5c096', 'bf3182e2-39d2-4ba6-9bc5-381bd6af5552', '2009-11-10 07:00:42.015906', '2009-11-10 07:41:23.068500')]
(Background on this error at: https://sqlalche.me/e/14/gkpj)
[2022-11-13T16:39:28.421+0000] {taskinstance.py:1406} INFO - Marking task as FAILED. dag_id=Assignment-7, task_id=copy_views, execution_date=20221113T163904, start_date=20221113T163905, end_date=20221113T163928
[2022-11-13T16:39:28.463+0000] {standard_task_runner.py:107} ERROR - Failed to execute job 11 for task copy_views ((psycopg2.errors.ForeignKeyViolation) insert or update on table "views" violates foreign key constraint "views_video_id_fkey"
DETAIL:  Key (video_id)=(bf3182e2-39d2-4ba6-9bc5-381bd6af5552) is not present in table "videos".

[SQL: INSERT INTO views VALUES ('d7433450-dd20-4162-97ec-810ae8bc45af', 'b4c28b89-6d8d-4b47-9d71-160643e5c096', 'bf3182e2-39d2-4ba6-9bc5-381bd6af5552', '2009-11-10 07:00:42.015906', '2009-11-10 07:41:23.068500')]
(Background on this error at: https://sqlalche.me/e/14/gkpj); 4476)
[2022-11-13T16:39:28.524+0000] {local_task_job.py:164} INFO - Task exited with return code 1
[2022-11-13T16:39:28.620+0000] {local_task_job.py:273} INFO - 0 downstream tasks scheduled from follow-on schedule check
